<?xml version="1.0"?>
<robot xmlns:xacro="http://www.ros.org/wiki/xacro" name="HS220">
    <!-- Links -->

    <link name="HS220"/>
	
    <link
    name="base_link">
    <inertial>
      <origin
        xyz="-0.100644956728846 4.29767897883229E-06 0.126791662916372"
        rpy="0 0 0" />
      <mass
        value="72.5187125015688" />
      <inertia
        ixx="1.58669092296512"
        ixy="-0.00123888358959699"
        ixz="0.214419384513568"
        iyy="2.81160955547976"
        iyz="-0.000609798588407871"
        izz="3.98978894382832" />
    </inertial>
    <visual>
      <origin
        xyz="0 0 0"
        rpy="0 0 0" />
      <geometry>
        <mesh
          filename="package://ned2_moveit/HS220/meshes/HS220_mesh_cylinder/base_link.STL" />
      </geometry>
      <material
        name="">
        <color
          rgba="0.792156862745098 0.819607843137255 0.933333333333333 1" />
      </material>
    </visual>
    <collision>
      <origin
        xyz="0 0 0"
        rpy="0 0 0" />
      <geometry>
        <mesh
          filename="package://ned2_moveit/HS220/meshes/HS220_mesh_cylinder/base_link.STL" />
      </geometry>
    </collision>
  </link>
  <link
    name="link1">
    <inertial>
      <origin
        xyz="0.0991849282377896 0.040288941012654 0.176112911574441"
        rpy="0 0 0" />
      <mass
        value="48.3859437832523" />
      <inertia
        ixx="1.25422735552633"
        ixy="-0.128065365533433"
        ixz="-0.491694656081483"
        iyy="1.78950817989833"
        iyz="-0.0636253207494512"
        izz="1.67680319314581" />
    </inertial>
    <visual>
      <origin
        xyz="0 0 0"
        rpy="0 0 0" />
      <geometry>
        <mesh
          filename="package://ned2_moveit/HS220/meshes/HS220_mesh_cylinder/link1.STL" />
      </geometry>
      <material
        name="">
        <color
          rgba="0.792156862745098 0.819607843137255 0.933333333333333 1" />
      </material>
    </visual>
    <collision>
      <origin
        xyz="0 0 0"
        rpy="0 0 0" />
      <geometry>
        <mesh
          filename="package://ned2_moveit/HS220/meshes/HS220_mesh_cylinder/link1.STL" />
      </geometry>
    </collision>
  </link>
  <joint name="joint_world" type="fixed">
        <parent link="HS220"/>
        <child link="base_link"/>
        <origin xyz="0 0 0" rpy="0 0 0"/>
    </joint>
  <joint
    name="joint1"
    type="revolute">
    <origin
      xyz="0.0006505 7.3191E-05 0.253"
      rpy="0 0 0" />
    <parent
      link="base_link" />
    <child
      link="link1" />
    <axis
      xyz="0 0 1" />
    <limit
      lower="-3.142"
      upper="3.142"
      effort="2844"
      velocity="2.094" />
  </joint>
  <link
    name="link2">
    <inertial>
      <origin
        xyz="0.0733688503018251 -0.0796663210978575 0.503543810885862"
        rpy="0 0 0" />
      <mass
        value="47.9199954946577" />
      <inertia
        ixx="5.2230534580201"
        ixy="-0.00141677498286555"
        ixz="0.201030335440851"
        iyy="5.37707302796985"
        iyz="0.687541914827274"
        izz="0.719097399552003" />
    </inertial>
    <visual>
      <origin
        xyz="0 0 0"
        rpy="0 0 0" />
      <geometry>
        <mesh
          filename="package://ned2_moveit/HS220/meshes/HS220_mesh_cylinder/link2.STL" />
      </geometry>
      <material
        name="">
        <color
          rgba="0.792156862745098 0.819607843137255 0.933333333333333 1" />
      </material>
    </visual>
    <collision>
      <origin
        xyz="0 0 0"
        rpy="0 0 0" />
      <geometry>
        <mesh
          filename="package://ned2_moveit/HS220/meshes/HS220_mesh_cylinder/link2.STL" />
      </geometry>
    </collision>
  </link>
  <joint
    name="joint2"
    type="revolute">
    <origin
      xyz="0.31135 -0.13607 0.355"
      rpy="0 0 0" />
    <parent
      link="link1" />
    <child
      link="link2" />
    <axis
      xyz="0 -1 0" />
    <limit
      lower="0.175"
      upper="2.705"
      effort="2844"
      velocity="1.833" />
  </joint>
  <link
    name="link3">
    <inertial>
      <origin
        xyz="0.18639 0.20251 0.11905"
        rpy="0 0 0" />
      <mass
        value="57.421" />
      <inertia
        ixx="0.59896"
        ixy="-0.024932"
        ixz="-0.060758"
        iyy="1.4319"
        iyz="-0.027357"
        izz="1.1563" />
    </inertial>
    <visual>
      <origin
        xyz="0 0 0"
        rpy="0 0 0" />
      <geometry>
        <mesh
          filename="package://ned2_moveit/HS220/meshes/HS220_mesh_cylinder/link3.STL" />
      </geometry>
      <material
        name="">
        <color
          rgba="0.79216 0.81961 0.93333 1" />
      </material>
    </visual>
    <collision>
      <origin
        xyz="0 0 0"
        rpy="0 0 0" />
      <geometry>
        <mesh
          filename="package://ned2_moveit/HS220/meshes/HS220_mesh_cylinder/link3.STL" />
      </geometry>
    </collision>
  </link>
  <joint
    name="joint3"
    type="revolute">
    <origin
      xyz="0 -0.094 1.1"
      rpy="0 0 0" />
    <parent
      link="link2" />
    <child
      link="link3" />
    <axis
      xyz="0 -1 0" />
    <limit
      lower="-1.396"
      upper="3.316"
      effort="2844"
      velocity="3.84" />
  </joint>
  <link
    name="link4">
    <inertial>
      <origin
        xyz="0.0523073390758193 -0.00267087351198795 2.22416878372655E-05"
        rpy="0 0 0" />
      <mass
        value="5.26542963939293" />
      <inertia
        ixx="0.0172754929839075"
        ixy="0.00152121551372902"
        ixz="-6.8322278105294E-06"
        iyy="0.0339691454257283"
        iyz="6.4643686534419E-07"
        izz="0.0333326570100911" />
    </inertial>
    <visual>
      <origin
        xyz="0 0 0"
        rpy="0 0 0" />
      <geometry>
        <mesh
          filename="package://ned2_moveit/HS220/meshes/HS220_mesh_cylinder/link4.STL" />
      </geometry>
      <material
        name="">
        <color
          rgba="0.792156862745098 0.819607843137255 0.933333333333333 1" />
      </material>
    </visual>
    <collision>
      <origin
        xyz="0 0 0"
        rpy="0 0 0" />
      <geometry>
        <mesh
          filename="package://ned2_moveit/HS220/meshes/HS220_mesh_cylinder/link4.STL" />
      </geometry>
    </collision>
  </link>
  <joint
    name="joint4"
    type="revolute">
    <origin
      xyz="1.02640195314655 0.229999999999997 0.230437151034579"
      rpy="0 0 0" />
    <parent
      link="link3" />
    <child
      link="link4" />
    <axis
      xyz="0.999999918458486 0 0.000403835389508935" />
    <limit
      lower="-6.284"
      upper="6.284"
      effort="1422"
      velocity="2.531" />
  </joint>
  <link
    name="link5">
    <inertial>
      <origin
        xyz="0.0270336208290114 0.0151880983630961 8.01018187135405E-05"
        rpy="0 0 0" />
      <mass
        value="6.25598597125955" />
      <inertia
        ixx="0.0273352498689108"
        ixy="0.000470365654334329"
        ixz="-4.06890428158186E-05"
        iyy="0.0370764096490186"
        iyz="5.68010524247413E-06"
        izz="0.03500416903498" />
    </inertial>
    <visual>
      <origin
        xyz="0 0 0"
        rpy="0 0 0" />
      <geometry>
        <mesh
          filename="package://ned2_moveit/HS220/meshes/HS220_mesh_cylinder/link5.STL" />
      </geometry>
      <material
        name="">
        <color
          rgba="0.792156862745098 0.819607843137255 0.933333333333333 1" />
      </material>
    </visual>
    <collision>
      <origin
        xyz="0 0 0"
        rpy="0 0 0" />
      <geometry>
        <mesh
          filename="package://ned2_moveit/HS220/meshes/HS220_mesh_cylinder/link5.STL" />
      </geometry>
    </collision>
  </link>
  <joint
    name="joint5"
    type="revolute">
    <origin
      xyz="0.2235 -0.055 9.5186E-05"
      rpy="0 0 0" />
    <parent
      link="link4" />
    <child
      link="link5" />
    <axis
      xyz="0 1 0" />
    <limit
      lower="-2.234"
      upper="2.234"
      effort="1422"
      velocity="2.531" />
  </joint>
  <link
    name="link6">
    <inertial>
      <origin
        xyz="0.039283 5.2391E-06 1.6713E-05"
        rpy="0 0 0" />
      <mass
        value="1.5928" />
      <inertia
        ixx="0.0054416"
        ixy="-3.7315E-07"
        ixz="8.5122E-07"
        iyy="0.0034471"
        iyz="4.4156E-07"
        izz="0.003445" />
    </inertial>
    <visual>
      <origin
        xyz="0 0 0"
        rpy="0 0 0" />
      <geometry>
        <mesh
          filename="package://ned2_moveit/HS220/meshes/HS220_mesh_cylinder/link6.STL" />
      </geometry>
      <material
        name="">
        <color
          rgba="0.79216 0.81961 0.93333 1" />
      </material>
    </visual>
    <collision>
      <origin
        xyz="0 0 0"
        rpy="0 0 0" />
      <geometry>
        <mesh
          filename="package://ned2_moveit/HS220/meshes/HS220_mesh_cylinder/link6.STL" />
      </geometry>
    </collision>
  </link>
  <joint
    name="joint6"
    type="revolute">
    <origin
      xyz="0.13599998766624 0.0549999999999999 5.79204846258285E-05"
      rpy="0 0 0" />
    <parent
      link="link5" />
    <child
      link="link6" />
    <axis
      xyz="-0.999999909310589 0 -0.000425885916354603" />
    <limit
      lower="-6.284"
      upper="6.284"
      effort="770"
      velocity="3.84" />
  </joint>
</robot>
